{
 "cells": [
  {
   "cell_type": "markdown",
   "id": "fa4319e7",
   "metadata": {},
   "source": [
    "# 1. What is the role of try and exception block?"
   ]
  },
  {
   "cell_type": "markdown",
   "id": "f408c819",
   "metadata": {},
   "source": [
    "The try block lets you test a block of code for errors.The except block lets you handle the error."
   ]
  },
  {
   "cell_type": "markdown",
   "id": "9946bcc4",
   "metadata": {},
   "source": [
    "# 2. What is the syntax for a basic try-except block?"
   ]
  },
  {
   "cell_type": "code",
   "execution_count": 1,
   "id": "653dbbc5",
   "metadata": {},
   "outputs": [
    {
     "name": "stdout",
     "output_type": "stream",
     "text": [
      "An exception occurred\n"
     ]
    }
   ],
   "source": [
    "try:\n",
    "    print(x)\n",
    "except:\n",
    "    print(\"An exception occurred\")\n",
    "\n",
    "    \"\"\"The try block raises an error, the except block will be executed.\n",
    "    Without the try block, the program will crash and raise an error\"\"\""
   ]
  },
  {
   "cell_type": "markdown",
   "id": "917713b5",
   "metadata": {},
   "source": [
    "# 3. What happens if an exception occurs inside a try block and there is no matching except block?"
   ]
  },
  {
   "cell_type": "markdown",
   "id": "d00cfcd5",
   "metadata": {},
   "source": [
    "If an exception occurs which does not match the exception named in the except clause, it is passed on to outer try statements; if no handler is found, it is an unhandled exception and execution stops with a message particular error message."
   ]
  },
  {
   "cell_type": "code",
   "execution_count": 2,
   "id": "5e7894b9",
   "metadata": {},
   "outputs": [
    {
     "name": "stdout",
     "output_type": "stream",
     "text": [
      "enter a number: 4\n",
      "enter a number: 2\n"
     ]
    },
    {
     "ename": "TypeError",
     "evalue": "unsupported operand type(s) for +: 'int' and 'str'",
     "output_type": "error",
     "traceback": [
      "\u001b[1;31m---------------------------------------------------------------------------\u001b[0m",
      "\u001b[1;31mTypeError\u001b[0m                                 Traceback (most recent call last)",
      "Cell \u001b[1;32mIn[2], line 5\u001b[0m\n\u001b[0;32m      3\u001b[0m m\u001b[38;5;241m=\u001b[39m\u001b[38;5;28mint\u001b[39m(\u001b[38;5;28minput\u001b[39m(\u001b[38;5;124m\"\u001b[39m\u001b[38;5;124menter a number: \u001b[39m\u001b[38;5;124m\"\u001b[39m))\n\u001b[0;32m      4\u001b[0m p\u001b[38;5;241m=\u001b[39mn\u001b[38;5;241m/\u001b[39mm\n\u001b[1;32m----> 5\u001b[0m q\u001b[38;5;241m=\u001b[39mn\u001b[38;5;241m+\u001b[39m\u001b[38;5;124m'\u001b[39m\u001b[38;5;124mm\u001b[39m\u001b[38;5;124m'\u001b[39m\n\u001b[0;32m      6\u001b[0m \u001b[38;5;28mprint\u001b[39m(p)\n\u001b[0;32m      7\u001b[0m \u001b[38;5;28mprint\u001b[39m(q)\n",
      "\u001b[1;31mTypeError\u001b[0m: unsupported operand type(s) for +: 'int' and 'str'"
     ]
    }
   ],
   "source": [
    "try:\n",
    "    n=int(input(\"enter a number: \"))\n",
    "    m=int(input(\"enter a number: \"))\n",
    "    p=n/m\n",
    "    q=n+'m'\n",
    "    print(p)\n",
    "    print(q)\n",
    "except ZeroDivisionError:\n",
    "    print(\"division by zero\")\n",
    "    \n",
    "#except TypeError:\n",
    " #   print(\"data type missmatch in addition\")\n",
    "    \n",
    "except ValueError:\n",
    "    print(\"it is integer you gave float\")\n",
    "    \n"
   ]
  },
  {
   "cell_type": "markdown",
   "id": "e748a98e",
   "metadata": {},
   "source": [
    "# 4. What is the difference between using a bare except block and specifying a specific exception type?"
   ]
  },
  {
   "cell_type": "markdown",
   "id": "0d283405",
   "metadata": {},
   "source": [
    "Handling exceptions without specifying an exception type in except-clause, and without performing any meaningful action in the exception handler, is not critical, but might hide actual programming errors. Hence, this is not considered pythonic. By not specifiycing an exception type,we might also loose information about the error itself.\n",
    "A bare except: clause will catch SystemExit and KeyboardInterrupt exceptions, making it harder to interrupt a program with Control-C, and can disguise other problems. If you want to catch all exceptions that signal program errors, use except Exception: (bare except is equivalent to except BaseException"
   ]
  },
  {
   "cell_type": "markdown",
   "id": "c56cca3d",
   "metadata": {},
   "source": [
    "The point of specifying the Exception is that ONLY that Exception will be caught, if you do not specify any Exception, then ALL Errors and Exceptions will be caught potentially masking bugs.For example let's say that we want to read a file if it exists or otherwise print a message to the user, I can write:"
   ]
  },
  {
   "cell_type": "code",
   "execution_count": 8,
   "id": "1c188730",
   "metadata": {},
   "outputs": [
    {
     "name": "stdout",
     "output_type": "stream",
     "text": [
      "File not found\n"
     ]
    }
   ],
   "source": [
    "try:\n",
    "    with ope(\"example.txt\", \"r\") as f:\n",
    "        print(f.read())\n",
    "except:\n",
    "    print(\"File not found\")"
   ]
  },
  {
   "cell_type": "markdown",
   "id": "241b139a",
   "metadata": {},
   "source": [
    "But while this code runs fine without raising any exceptions, this code will never read the file, even if it exists!!!\n",
    "This is because we wrote ope instead of open and the NameError was caught by my bare except, If I write the except in the correct way:"
   ]
  },
  {
   "cell_type": "code",
   "execution_count": 9,
   "id": "0a9986ba",
   "metadata": {},
   "outputs": [
    {
     "ename": "NameError",
     "evalue": "name 'ope' is not defined",
     "output_type": "error",
     "traceback": [
      "\u001b[1;31m---------------------------------------------------------------------------\u001b[0m",
      "\u001b[1;31mNameError\u001b[0m                                 Traceback (most recent call last)",
      "Cell \u001b[1;32mIn[9], line 2\u001b[0m\n\u001b[0;32m      1\u001b[0m \u001b[38;5;28;01mtry\u001b[39;00m:\n\u001b[1;32m----> 2\u001b[0m     \u001b[38;5;28;01mwith\u001b[39;00m ope(\u001b[38;5;124m\"\u001b[39m\u001b[38;5;124mexample.txt\u001b[39m\u001b[38;5;124m\"\u001b[39m, \u001b[38;5;124m\"\u001b[39m\u001b[38;5;124mr\u001b[39m\u001b[38;5;124m\"\u001b[39m) \u001b[38;5;28;01mas\u001b[39;00m f:\n\u001b[0;32m      3\u001b[0m         \u001b[38;5;28mprint\u001b[39m(f\u001b[38;5;241m.\u001b[39mread())\n\u001b[0;32m      4\u001b[0m \u001b[38;5;28;01mexcept\u001b[39;00m \u001b[38;5;167;01mFileNotFoundError\u001b[39;00m:\n",
      "\u001b[1;31mNameError\u001b[0m: name 'ope' is not defined"
     ]
    }
   ],
   "source": [
    "try:\n",
    "    with ope(\"example.txt\", \"r\") as f:\n",
    "        print(f.read())\n",
    "except FileNotFoundError:\n",
    "    print(\"File not found\")\n",
    "# Now we can properly debug my code:"
   ]
  },
  {
   "cell_type": "code",
   "execution_count": 12,
   "id": "a80beca8",
   "metadata": {},
   "outputs": [
    {
     "name": "stdout",
     "output_type": "stream",
     "text": [
      "File not found\n"
     ]
    }
   ],
   "source": [
    "try:\n",
    "    with open(\"example1.txt\", \"r\") as f:\n",
    "        print(f.read())\n",
    "except FileNotFoundError:\n",
    "    print(\"File not found\")"
   ]
  },
  {
   "cell_type": "markdown",
   "id": "61e3cee5",
   "metadata": {},
   "source": [
    "# 5. Can you have nested try-except blocks in Python? If yes, then give an example."
   ]
  },
  {
   "cell_type": "code",
   "execution_count": 13,
   "id": "1d744bea",
   "metadata": {},
   "outputs": [
    {
     "name": "stdout",
     "output_type": "stream",
     "text": [
      "outer try block\n",
      "nested try block\n",
      "outer except block\n",
      "division by zero\n"
     ]
    }
   ],
   "source": [
    "x = 10\n",
    "y = 0\n",
    "\n",
    "try:\n",
    "    print(\"outer try block\")\n",
    "    try:\n",
    "        print(\"nested try block\")\n",
    "        print(x / y)\n",
    "    except TypeError as te:\n",
    "        print(\"nested except block\")\n",
    "        print(te)\n",
    "except ZeroDivisionError as ze:\n",
    "    print(\"outer except block\")\n",
    "    print(ze)"
   ]
  },
  {
   "cell_type": "markdown",
   "id": "067ac313",
   "metadata": {},
   "source": [
    "# 6. Can we use multiple exception blocks, if yes then give an example."
   ]
  },
  {
   "cell_type": "code",
   "execution_count": 14,
   "id": "9816713b",
   "metadata": {},
   "outputs": [
    {
     "name": "stdout",
     "output_type": "stream",
     "text": [
      "enter a number: 5\n",
      "enter a number: 2\n",
      "data type missmatch in addition\n"
     ]
    }
   ],
   "source": [
    "try:\n",
    "    n=int(input(\"enter a number: \"))\n",
    "    m=int(input(\"enter a number: \"))\n",
    "    p=n/m\n",
    "    q=n+'m'\n",
    "    print(p)\n",
    "    print(q)\n",
    "except ZeroDivisionError:\n",
    "    print(\"division by zero\")\n",
    "    \n",
    "except TypeError:\n",
    "    print(\"data type missmatch in addition\")\n",
    "    \n",
    "except ValueError:\n",
    "    print(\"it is integer you gave float\")\n",
    "    \n"
   ]
  },
  {
   "cell_type": "markdown",
   "id": "1bde37ba",
   "metadata": {},
   "source": [
    "# 7. Write the reason due to which following errors are raised:\n",
    "a. EOFError\n",
    "b. FloatingPointError\n",
    "c. IndexError\n",
    "d. MemoryError\n",
    "e. OverflowError\n",
    "f. TabError\n",
    "g. ValueError"
   ]
  },
  {
   "cell_type": "markdown",
   "id": "f2fe0dde",
   "metadata": {},
   "source": [
    "a. EOFError\n",
    "EOF stands for \"end of file,\" and this syntax error occurs when Python detects an unfinished statement or block of code. This can happen for many reasons, but the most likely cause is missing punctuation or an incorrectly indented block.\n",
    "SyntaxError: unexpected EOF while parsing"
   ]
  },
  {
   "cell_type": "code",
   "execution_count": 15,
   "id": "59ee2525",
   "metadata": {},
   "outputs": [
    {
     "ename": "SyntaxError",
     "evalue": "incomplete input (428827410.py, line 1)",
     "output_type": "error",
     "traceback": [
      "\u001b[1;36m  Cell \u001b[1;32mIn[15], line 1\u001b[1;36m\u001b[0m\n\u001b[1;33m    print('This is a test'\u001b[0m\n\u001b[1;37m                          ^\u001b[0m\n\u001b[1;31mSyntaxError\u001b[0m\u001b[1;31m:\u001b[0m incomplete input\n"
     ]
    }
   ],
   "source": [
    "print('This is a test'"
   ]
  },
  {
   "cell_type": "code",
   "execution_count": 19,
   "id": "e735a544",
   "metadata": {},
   "outputs": [
    {
     "name": "stdout",
     "output_type": "stream",
     "text": [
      "This is a test\n"
     ]
    }
   ],
   "source": [
    "print('This is a test')"
   ]
  },
  {
   "cell_type": "markdown",
   "id": "748d9b6b",
   "metadata": {},
   "source": [
    "b. FloatingPointError\n",
    "It's a problem caused when the internal representation of floating-point numbers, which uses a fixed number of binary digits to represent a decimal number. It is difficult to represent some decimal number in binary, so in many cases, it leads to small roundoff errors.Python float values are represented as 64-bit double-precision values.In this case, taking 1.2 as an example, the representation of 0.2 in binary is 0.00110011001100110011001100…… and so on. It is difficult to store this infinite decimal number internally. Normally a float object’s value is stored in binary floating-point with a fixed precision (typically 53 bits). So we represent 1.2 internally as,\n",
    "\n",
    "1.0011001100110011001100110011001100110011001100110011  \n",
    "Which is exactly equal to :\n",
    "\n",
    "1.1999999999999999555910790149937383830547332763671875"
   ]
  },
  {
   "cell_type": "code",
   "execution_count": 1,
   "id": "08b17941",
   "metadata": {},
   "outputs": [
    {
     "data": {
      "text/plain": [
       "0.19999999999999996"
      ]
     },
     "execution_count": 1,
     "metadata": {},
     "output_type": "execute_result"
    }
   ],
   "source": [
    "1.2-1.0"
   ]
  },
  {
   "cell_type": "markdown",
   "id": "0e895a94",
   "metadata": {},
   "source": [
    "c. IndexError\n",
    "the IndexError is a common exception that occurs when trying to access an element in a list, tuple, or any other sequence using an index that is outside the valid range of indices for that sequence."
   ]
  },
  {
   "cell_type": "code",
   "execution_count": 6,
   "id": "75214da9",
   "metadata": {},
   "outputs": [
    {
     "ename": "IndexError",
     "evalue": "list index out of range",
     "output_type": "error",
     "traceback": [
      "\u001b[1;31m---------------------------------------------------------------------------\u001b[0m",
      "\u001b[1;31mIndexError\u001b[0m                                Traceback (most recent call last)",
      "Cell \u001b[1;32mIn[6], line 2\u001b[0m\n\u001b[0;32m      1\u001b[0m a \u001b[38;5;241m=\u001b[39m [\u001b[38;5;241m1\u001b[39m, \u001b[38;5;241m2\u001b[39m, \u001b[38;5;241m4\u001b[39m]\n\u001b[1;32m----> 2\u001b[0m a[\u001b[38;5;241m4\u001b[39m]\n",
      "\u001b[1;31mIndexError\u001b[0m: list index out of range"
     ]
    }
   ],
   "source": [
    "a = [1, 2, 4]\n",
    "a[4]"
   ]
  },
  {
   "cell_type": "markdown",
   "id": "3c28b921",
   "metadata": {},
   "source": [
    "d. MemoryError\n",
    "A MemoryError means that the interpreter has run out of memory to allocate to your Python program. This may be due to an issue in the setup of the Python environment or it may be a concern with the code itself loading too much data at the same time.\n"
   ]
  },
  {
   "cell_type": "code",
   "execution_count": 7,
   "id": "0da487e8",
   "metadata": {},
   "outputs": [
    {
     "ename": "MemoryError",
     "evalue": "",
     "output_type": "error",
     "traceback": [
      "\u001b[1;31m---------------------------------------------------------------------------\u001b[0m",
      "\u001b[1;31mMemoryError\u001b[0m                               Traceback (most recent call last)",
      "Cell \u001b[1;32mIn[7], line 5\u001b[0m\n\u001b[0;32m      3\u001b[0m \u001b[38;5;28;01mfor\u001b[39;00m j \u001b[38;5;129;01min\u001b[39;00m \u001b[38;5;28mrange\u001b[39m(\u001b[38;5;241m1000\u001b[39m):\n\u001b[0;32m      4\u001b[0m     \u001b[38;5;28;01mfor\u001b[39;00m k \u001b[38;5;129;01min\u001b[39;00m \u001b[38;5;28mrange\u001b[39m(\u001b[38;5;241m1000\u001b[39m):\n\u001b[1;32m----> 5\u001b[0m         s\u001b[38;5;241m.\u001b[39mappend(\u001b[38;5;124m\"\u001b[39m\u001b[38;5;124mMore\u001b[39m\u001b[38;5;124m\"\u001b[39m)\n",
      "\u001b[1;31mMemoryError\u001b[0m: "
     ]
    }
   ],
   "source": [
    "s = []\n",
    "for i in range(1000):\n",
    "    for j in range(1000):\n",
    "        for k in range(1000):\n",
    "            s.append(\"More\")"
   ]
  },
  {
   "cell_type": "markdown",
   "id": "34451211",
   "metadata": {},
   "source": [
    "e. OverflowError\n",
    "OverflowError occurs when any operations like arithmetic operations or any other variable storing any value above its limit then there occurs an overflow of values that will exceed it's specified or already defined limit.In Python this error occurs when an arithmetic operation result is stored in any variable where the result value is larger than any given data type like float, int, etc exceeds the limit or value of current Python runtime values. Therefore when these values are larger than the declared data type values will result to raise memory errors."
   ]
  },
  {
   "cell_type": "code",
   "execution_count": 8,
   "id": "e3f6fad4",
   "metadata": {},
   "outputs": [
    {
     "name": "stdout",
     "output_type": "stream",
     "text": [
      "Simple program for showing overflow error\n",
      "\n",
      "\n",
      "The exponential value is\n"
     ]
    },
    {
     "ename": "OverflowError",
     "evalue": "math range error",
     "output_type": "error",
     "traceback": [
      "\u001b[1;31m---------------------------------------------------------------------------\u001b[0m",
      "\u001b[1;31mOverflowError\u001b[0m                             Traceback (most recent call last)",
      "Cell \u001b[1;32mIn[8], line 5\u001b[0m\n\u001b[0;32m      3\u001b[0m \u001b[38;5;28;01mimport\u001b[39;00m \u001b[38;5;21;01mmath\u001b[39;00m\n\u001b[0;32m      4\u001b[0m \u001b[38;5;28mprint\u001b[39m(\u001b[38;5;124m\"\u001b[39m\u001b[38;5;124mThe exponential value is\u001b[39m\u001b[38;5;124m\"\u001b[39m)\n\u001b[1;32m----> 5\u001b[0m \u001b[38;5;28mprint\u001b[39m(math\u001b[38;5;241m.\u001b[39mexp(\u001b[38;5;241m1000\u001b[39m))\n",
      "\u001b[1;31mOverflowError\u001b[0m: math range error"
     ]
    }
   ],
   "source": [
    "print(\"Simple program for showing overflow error\")\n",
    "print(\"\\n\")\n",
    "import math\n",
    "print(\"The exponential value is\")\n",
    "print(math.exp(1000))"
   ]
  },
  {
   "cell_type": "markdown",
   "id": "a907fb2b",
   "metadata": {},
   "source": [
    "f. TabError\n",
    "Inconsistent use of tabs and spaces in indentation\" occurs when we mix tabs and spaces in the same code block. To solve the error, remove the spacing and only use tabs or spaces, but don't mix the two in the same code block."
   ]
  },
  {
   "cell_type": "markdown",
   "id": "f3368c62",
   "metadata": {},
   "source": [
    "g. ValueError\n",
    "A ValueError occurs when a correct argument type but an incorrect value is supplied to a function. This type of inaccuracy is most common in mathematical operations. A TypeError, as opposed to a ValueError, is raised when an operation is performed that is using an incorrect or unsupported object type."
   ]
  },
  {
   "cell_type": "code",
   "execution_count": 21,
   "id": "47cb9dd5",
   "metadata": {},
   "outputs": [
    {
     "ename": "ValueError",
     "evalue": "math domain error",
     "output_type": "error",
     "traceback": [
      "\u001b[1;31m---------------------------------------------------------------------------\u001b[0m",
      "\u001b[1;31mValueError\u001b[0m                                Traceback (most recent call last)",
      "Cell \u001b[1;32mIn[21], line 2\u001b[0m\n\u001b[0;32m      1\u001b[0m \u001b[38;5;28;01mimport\u001b[39;00m \u001b[38;5;21;01mmath\u001b[39;00m\n\u001b[1;32m----> 2\u001b[0m math\u001b[38;5;241m.\u001b[39msqrt(\u001b[38;5;241m-\u001b[39m\u001b[38;5;241m20\u001b[39m)\n",
      "\u001b[1;31mValueError\u001b[0m: math domain error"
     ]
    }
   ],
   "source": [
    "import math\n",
    "math.sqrt(-20)\n"
   ]
  },
  {
   "cell_type": "markdown",
   "id": "47fc00c4",
   "metadata": {},
   "source": [
    "# 8. Write code for the following given scenario and add try-exception block to it.\n",
    "a. Program to divide two numbers\n",
    "b. Program to convert a string to an integer\n",
    "c. Program to access an element in a list\n",
    "d. Program to handle a specific exception\n",
    "e. Program to handle any exception"
   ]
  },
  {
   "cell_type": "code",
   "execution_count": 31,
   "id": "9e31aff6",
   "metadata": {},
   "outputs": [
    {
     "name": "stdout",
     "output_type": "stream",
     "text": [
      "first number:-5\n",
      "second number:-4\n",
      "negative number not allowed \n"
     ]
    }
   ],
   "source": [
    "# a. Program to divide two numbers\n",
    "try:\n",
    "    a=int(input(\"first number:\") )\n",
    "    b=int(input(\"second number:\"))\n",
    "    if a<0 or b<0: \n",
    "        raise Exception(\"negative number not allowed \")  # built-in class \n",
    "    c=a/b\n",
    "    print(\"div: \", c)\n",
    "except ValueError:\n",
    "    print(\"please enter integer only\")\n",
    "except ZeroDivisionError:\n",
    "    print(\"please enter nonzero denominator\")\n",
    "except Exception as e:\n",
    "    print(e)"
   ]
  },
  {
   "cell_type": "code",
   "execution_count": 5,
   "id": "a3e36f2f",
   "metadata": {},
   "outputs": [
    {
     "name": "stdout",
     "output_type": "stream",
     "text": [
      "enter any number: -5\n"
     ]
    }
   ],
   "source": [
    "# b. Program to convert a string to an integer\n",
    "try:\n",
    "    x=input(\"enter any number: \")\n",
    "    a=int(x)\n",
    "except ValueError:\n",
    "    print(\"enter integers only\")"
   ]
  },
  {
   "cell_type": "code",
   "execution_count": 2,
   "id": "de121b22",
   "metadata": {},
   "outputs": [
    {
     "data": {
      "text/plain": [
       "str"
      ]
     },
     "execution_count": 2,
     "metadata": {},
     "output_type": "execute_result"
    }
   ],
   "source": [
    "type(x)"
   ]
  },
  {
   "cell_type": "code",
   "execution_count": 3,
   "id": "090f51fb",
   "metadata": {},
   "outputs": [
    {
     "data": {
      "text/plain": [
       "int"
      ]
     },
     "execution_count": 3,
     "metadata": {},
     "output_type": "execute_result"
    }
   ],
   "source": [
    "type(a)"
   ]
  },
  {
   "cell_type": "code",
   "execution_count": 8,
   "id": "9e55967e",
   "metadata": {},
   "outputs": [],
   "source": [
    "# c. Program to access an element in a list\n",
    "class NotFoundException(Exception):\n",
    "    pass"
   ]
  },
  {
   "cell_type": "code",
   "execution_count": 12,
   "id": "2beec49a",
   "metadata": {},
   "outputs": [
    {
     "name": "stdout",
     "output_type": "stream",
     "text": [
      "Enter number of elements : 5\n",
      "enter a number: 1\n",
      "enter a number: 2\n",
      "enter a number: 3\n",
      "enter a number: 4\n",
      "enter a number: 8\n",
      "[1, 2, 3, 4, 8]\n",
      "pick any number from the list:8\n",
      "a is found at index:  4\n"
     ]
    }
   ],
   "source": [
    "l=[]\n",
    "n = int(input(\"Enter number of elements : \"))\n",
    "for i in range(0, n):\n",
    "    x = int(input(\"enter a number: \"))\n",
    "    l.append(x)\n",
    "print(l)\n",
    "while True:\n",
    "    try:\n",
    "        a=int(input(\"pick any number from the list:\"))\n",
    "        if a not in l:\n",
    "            raise NotFoundException(\"enter elements present in the list\")\n",
    "        else:\n",
    "            print(\"a is found at index: \",l.index(a))\n",
    "        break\n",
    "    except Exception as e:\n",
    "        print(e)"
   ]
  },
  {
   "cell_type": "code",
   "execution_count": 7,
   "id": "b987fb9d",
   "metadata": {},
   "outputs": [
    {
     "name": "stdout",
     "output_type": "stream",
     "text": [
      "first number:5\n",
      "second number:0\n",
      "division by zero\n"
     ]
    }
   ],
   "source": [
    "# d. Program to handle a specific exception\n",
    "try:\n",
    "    a=int(input(\"first number:\"))\n",
    "    b=int(input(\"second number:\"))\n",
    "    c=a/b\n",
    "    print(\"div:\", c)\n",
    "except ZeroDivisionError as e:\n",
    "    print(e)"
   ]
  },
  {
   "cell_type": "code",
   "execution_count": 12,
   "id": "273ca9e9",
   "metadata": {},
   "outputs": [
    {
     "name": "stdout",
     "output_type": "stream",
     "text": [
      "first number:5\n",
      "second number:0\n",
      "division by zero\n"
     ]
    }
   ],
   "source": [
    "# e. Program to handle any exception\n",
    "try:\n",
    "    a=int(input(\"first number:\"))\n",
    "    b=int(input(\"second number:\"))\n",
    "    c=a/b\n",
    "    print(\"div:\", c)\n",
    "except Exception as e:\n",
    "    print(e)"
   ]
  },
  {
   "cell_type": "code",
   "execution_count": null,
   "id": "0ae078f5",
   "metadata": {},
   "outputs": [],
   "source": []
  }
 ],
 "metadata": {
  "kernelspec": {
   "display_name": "Python 3 (ipykernel)",
   "language": "python",
   "name": "python3"
  },
  "language_info": {
   "codemirror_mode": {
    "name": "ipython",
    "version": 3
   },
   "file_extension": ".py",
   "mimetype": "text/x-python",
   "name": "python",
   "nbconvert_exporter": "python",
   "pygments_lexer": "ipython3",
   "version": "3.11.4"
  }
 },
 "nbformat": 4,
 "nbformat_minor": 5
}
